## 에러를 처리하는 위치

- **예제 코드 : 에러가 발생하는 코드**
- 에러가 발생한다.
- 네트워크가 없다고 출력됨.

```tsx
class NetworkClient {
  tryConnect(): void {
    throw new Error("네트워크가 없습니다.");
  }
}

class UserService {
  constructor(private client: NetworkClient) {}

  login() {
    this.client.tryConnect();
  }
}

const client = new NetworkClient();
const service = new UserService(client);
service.login();
```

### **에러 핸들링의 위치**

**에러가 발생했을때 정확하게 에러를 처리할 수 없다면 catch하지 않는것이 더 낫다.**

에러를 처리하는 곳이 의미있게 처리할 수 있는 곳인지 고민해봐야한다.

- 에러를 login() 에서 잡을 경우 아무처리도 할 수 없다.
- 에러가 발생했는지는 catch에서 처리가 되기 때문에 확인 가능함.

```tsx
class NetworkClient {
  tryConnect(): void {
    throw new Error("네트워크가 없습니다.");
  }
}

class UserService {
  constructor(private client: NetworkClient) {}

  login() {
    try {
      this.client.tryConnect();
    } catch (error) {
      console.log("에러 잡음!");
    }
    // login 진행
  }
}

const client = new NetworkClient();
const service = new UserService(client);
// service.login();

class App {
  constructor(private userService: UserService) {}

  run() {
    this.userService.login();
  }
}

const app = new App(service);
app.run();
```

- 개선한 코드

```tsx
class NetworkClient {
  tryConnect(): void {
    throw new Error("네트워크가 없습니다.");
  }
}

class UserService {
  constructor(private client: NetworkClient) {}

  login() {
    this.client.tryConnect();
    // login 진행
  }
}

const client = new NetworkClient();
const service = new UserService(client);
// service.login();

class App {
  constructor(private userService: UserService) {}

  run() {
    try {
      this.userService.login();
    } catch (error) {
      // 여기서 안내 메시지를 보여주는 처리
    }
  }
}

const app = new App(service);
app.run();
```
